Workbook

Sheet Uebersicht
A1: Starkregen-Gefahrenanalyse Essen-Kupferdreh - Uebersicht
A2: Anzahl und Grundflaeche der Gebaeude je Risikoklasse (berechnet aus Blatt "Alle Gebaeude")
A4: Risikoklasse | B4: Bezeichnung | C4: Anzahl Gebaeude | D4: Anteil Anzahl (%) | E4: Grundflaeche (m2) | F4: Anteil Flaeche (%)
A5: 3 | B5: Hoch | C5: =COUNTIF('Alle Gebaeude'!H$5:H$2868,A5) | D5: =C5/C$9*100 | E5: =SUMIF('Alle Gebaeude'!H$5:H$2868,A5,'Alle Gebaeude'!E$5:E$2868) | F5: =E5/E$9*100
A6: 2 | B6: Mittel | C6: =COUNTIF('Alle Gebaeude'!H$5:H$2868,A6) | D6: =C6/C$9*100 | E6: =SUMIF('Alle Gebaeude'!H$5:H$2868,A6,'Alle Gebaeude'!E$5:E$2868) | F6: =E6/E$9*100
A7: 1 | B7: Gering | C7: =COUNTIF('Alle Gebaeude'!H$5:H$2868,A7) | D7: =C7/C$9*100 | E7: =SUMIF('Alle Gebaeude'!H$5:H$2868,A7,'Alle Gebaeude'!E$5:E$2868) | F7: =E7/E$9*100
A8: 0 | B8: Kein Risiko | C8: =COUNTIF('Alle Gebaeude'!H$5:H$2868,A8) | D8: =C8/C$9*100 | E8: =SUMIF('Alle Gebaeude'!H$5:H$2868,A8,'Alle Gebaeude'!E$5:E$2868) | F8: =E8/E$9*100
B9: Summe | C9: =SUM(C5:C8) | D9: =SUM(D5:D8) | E9: =SUM(E5:E8) | F9: =SUM(F5:F8)
A11: Gebaeude mit Risiko (Klasse 1-3) | C11: =C5+C6+C7 | D11: =D5+D6+D7

Sheet Strassen
A1: Strassen mit den meisten Gebaeuden der Risikoklasse Hoch
A2: Nur Gebaeude mit Strassenangabe in OpenStreetMap
A4: Rang | B4: Strasse | C4: Gebaeude Hoch | D4: Gebaeude Mittel | E4: Gebaeude Gering | F4: Gebaeude gesamt | G4: Max. Senkentiefe (m)
A5: 1 | B5: Kupferdreher Straße | C5: =COUNTIFS('Alle Gebaeude'!C$5:C$2868,B5,'Alle Gebaeude'!H$5:H$2868,3) | D5: =COUNTIFS('Alle Gebaeude'!C$5:C$2868,B5,'Alle Gebaeude'!H$5:H$2868,2) | E5: =COUNTIFS('Alle Gebaeude'!C$5:C$2868,B5,'Alle Gebaeude'!H$5:H$2868,1) | F5: =COUNTIF('Alle Gebaeude'!C$5:C$2868,B5) | G5: =_xlfn.MAXIFS('Alle Gebaeude'!F$5:F$2868,'Alle Gebaeude'!C$5:C$2868,B5)
A6: 2 | B6: Byfanger Straße | C6: =COUNTIFS('Alle Gebaeude'!C$5:C$2868,B6,'Alle Gebaeude'!H$5:H$2868,3) | D6: =COUNTIFS('Alle Gebaeude'!C$5:C$2868,B6,'Alle Gebaeude'!H$5:H$2868,2) | E6: =COUNTIFS('Alle Gebaeude'!C$5:C$2868,B6,'Alle Gebaeude'!H$5:H$2868,1) | F6: =COUNTIF('Alle Gebaeude'!C$5:C$2868,B6) | G6: =_xlfn.MAXIFS('Alle Gebaeude'!F$5:F$2868,'Alle Gebaeude'!C$5:C$2868,B6)
A7: 3 | B7: Hinsbecker Löh | C7: =COUNTIFS('Alle Gebaeude'!C$5:C$2868,B7,'Alle Gebaeude'!H$5:H$2868,3) | D7: =COUNTIFS('Alle Gebaeude'!C$5:C$2868,B7,'Alle Gebaeude'!H$5:H$2868,2) | E7: =COUNTIFS('Alle Gebaeude'!C$5:C$2868,B7,'Alle Gebaeude'!H$5:H$2868,1) | F7: =COUNTIF('Alle Gebaeude'!C$5:C$2868,B7) | G7: =_xlfn.MAXIFS('Alle Gebaeude'!F$5:F$2868,'Alle Gebaeude'!C$5:C$2868,B7)
A8: 4 | B8: Colsmanstraße | C8: =COUNTIFS('Alle Gebaeude'!C$5:C$2868,B8,'Alle Gebaeude'!H$5:H$2868,3) | D8: =COUNTIFS('Alle Gebaeude'!C$5:C$2868,B8,'Alle Gebaeude'!H$5:H$2868,2) | E8: =COUNTIFS('Alle Gebaeude'!C$5:C$2868,B8,'Alle Gebaeude'!H$5:H$2868,1) | F8: =COUNTIF('Alle Gebaeude'!C$5:C$2868,B8) | G8: =_xlfn.MAXIFS('Alle Gebaeude'!F$5:F$2868,'Alle Gebaeude'!C$5:C$2868,B8)
A9: 5 | B9: Blockstraße | C9: =COUNTIFS('Alle Gebaeude'!C$5:C$2868,B9,'Alle Gebaeude'!H$5:H$2868,3) | D9: =COUNTIFS('Alle Gebaeude'!C$5:C$2868,B9,'Alle Gebaeude'!H$5:H$2868,2) | E9: =COUNTIFS('Alle Gebaeude'!C$5:C$2868,B9,'Alle Gebaeude'!H$5:H$2868,1) | F9: =COUNTIF('Alle Gebaeude'!C$5:C$2868,B9) | G9: =_xlfn.MAXIFS('Alle Gebaeude'!F$5:F$2868,'Alle Gebaeude'!C$5:C$2868,B9)
A10: 6 | B10: Niederweniger Straße | C10: =COUNTIFS('Alle Gebaeude'!C$5:C$2868,B10,'Alle Gebaeude'!H$5:H$2868,3) | D10: =COUNTIFS('Alle Gebaeude'!C$5:C$2868,B10,'Alle Gebaeude'!H$5:H$2868,2) | E10: =COUNTIFS('Alle Gebaeude'!C$5:C$2868,B10,'Alle Gebaeude'!H$5:H$2868,1) | F10: =COUNTIF('Alle Gebaeude'!C$5:C$2868,B10) | G10: =_xlfn.MAXIFS('Alle Gebaeude'!F$5:F$2868,'Alle Gebaeude'!C$5:C$2868,B10)
A11: 7 | B11: Dixbäume | C11: =COUNTIFS('Alle Gebaeude'!C$5:C$2868,B11,'Alle Gebaeude'!H$5:H$2868,3) | D11: =COUNTIFS('Alle Gebaeude'!C$5:C$2868,B11,'Alle Gebaeude'!H$5:H$2868,2) | E11: =COUNTIFS('Alle Gebaeude'!C$5:C$2868,B11,'Alle Gebaeude'!H$5:H$2868,1) | F11: =COUNTIF('Alle Gebaeude'!C$5:C$2868,B11) | G11: =_xlfn.MAXIFS('Alle Gebaeude'!F$5:F$2868,'Alle Gebaeude'!C$5:C$2868,B11)
A12: 8 | B12: Deilbachbrücke | C12: =COUNTIFS('Alle Gebaeude'!C$5:C$2868,B12,'Alle Gebaeude'!H$5:H$2868,3) | D12: =COUNTIFS('Alle Gebaeude'!C$5:C$2868,B12,'Alle Gebaeude'!H$5:H$2868,2) | E12: =COUNTIFS('Alle Gebaeude'!C$5:C$2868,B12,'Alle Gebaeude'!H$5:H$2868,1) | F12: =COUNTIF('Alle Gebaeude'!C$5:C$2868,B12) | G12: =_xlfn.MAXIFS('Alle Gebaeude'!F$5:F$2868,'Alle Gebaeude'!C$5:C$2868,B12)
A13: 9 | B13: Möllneyer Ufer | C13: =COUNTIFS('Alle Gebaeude'!C$5:C$2868,B13,'Alle Gebaeude'!H$5:H$2868,3) | D13: =COUNTIFS('Alle Gebaeude'!C$5:C$2868,B13,'Alle Gebaeude'!H$5:H$2868,2) | E13: =COUNTIFS('Alle Gebaeude'!C$5:C$2868,B13,'Alle Gebaeude'!H$5:H$2868,1) | F13: =COUNTIF('Alle Gebaeude'!C$5:C$2868,B13) | G13: =_xlfn.MAXIFS('Alle Gebaeude'!F$5:F$2868,'Alle Gebaeude'!C$5:C$2868,B13)
A14: 10 | B14: Scharpenhang | C14: =COUNTIFS('Alle Gebaeude'!C$5:C$2868,B14,'Alle Gebaeude'!H$5:H$2868,3) | D14: =COUNTIFS('Alle Gebaeude'!C$5:C$2868,B14,'Alle Gebaeude'!H$5:H$2868,2) | E14: =COUNTIFS('Alle Gebaeude'!C$5:C$2868,B14,'Alle Gebaeude'!H$5:H$2868,1) | F14: =COUNTIF('Alle Gebaeude'!C$5:C$2868,B14) | G14: =_xlfn.MAXIFS('Alle Gebaeude'!F$5:F$2868,'Alle Gebaeude'!C$5:C$2868,B14)
A15: 11 | B15: Heidbergweg | C15: =COUNTIFS('Alle Gebaeude'!C$5:C$2868,B15,'Alle Gebaeude'!H$5:H$2868,3) | D15: =COUNTIFS('Alle Gebaeude'!C$5:C$2868,B15,'Alle Gebaeude'!H$5:H$2868,2) | E15: =COUNTIFS('Alle Gebaeude'!C$5:C$2868,B15,'Alle Gebaeude'!H$5:H$2868,1) | F15: =COUNTIF('Alle Gebaeude'!C$5:C$2868,B15) | G15: =_xlfn.MAXIFS('Alle Gebaeude'!F$5:F$2868,'Alle Gebaeude'!C$5:C$2868,B15)
A16: 12 | B16: Hinsbecker Berg | C16: =COUNTIFS('Alle Gebaeude'!C$5:C$2868,B16,'Alle Gebaeude'!H$5:H$2868,3) | D16: =COUNTIFS('Alle Gebaeude'!C$5:C$2868,B16,'Alle Gebaeude'!H$5:H$2868,2) | E16: =COUNTIFS('Alle Gebaeude'!C$5:C$2868,B16,'Alle Gebaeude'!H$5:H$2868,1) | F16: =COUNTIF('Alle Gebaeude'!C$5:C$2868,B16) | G16: =_xlfn.MAXIFS('Alle Gebaeude'!F$5:F$2868,'Alle Gebaeude'!C$5:C$2868,B16)
... A36: 32 | B36: Asbachtal | C36: =COUNTIFS('Alle Gebaeude'!C$5:C$2868,B36,'Alle Gebaeude'!H$5:H$2868,3) | D36: =COUNTIFS('Alle Gebaeude'!C$5:C$2868,B36,'Alle Gebaeude'!H$5:H$2868,2) | E36: =COUNTIFS('Alle Gebaeude'!C$5:C$2868,B36,'Alle Gebaeude'!H$5:H$2868,1) | F36: =COUNTIF('Alle Gebaeude'!C$5:C$2868,B36) | G36: =_xlfn.MAXIFS('Alle Gebaeude'!F$5:F$2868,'Alle Gebaeude'!C$5:C$2868,B36)

Sheet Alle Gebaeude
A1: Starkregenrisiko je Gebaeude - Essen-Kupferdreh
A2: Untersuchungsgebiet 2 x 2 km (EPSG:25832: 366000-368000 / 5694000-5696000), DGM1 NRW, Gebaeude OpenStreetMap
A4: OBJECTID | B4: Gebaeudetyp (OSM) | C4: Strasse | D4: Hausnr. | E4: Grundflaeche (m2) | F4: Max. Senkentiefe (m) | G4: Max. Strahler-Ordnung Fliessweg | H4: Risikoklasse | I4: Risiko
A5: 1 | B5: yes | C5: Frauenstein | D5: 119 | E5: 96.7 | F5: 0.069999695 | G5: 0 | H5: =IF(OR(N(F5)>=0.5,G5>=4),3,IF(OR(N(F5)>=0.3,G5=3),2,IF(OR(N(F5)>=0.1,G5>=1),1,0))) | I5: =CHOOSE(H5+1,"Kein Risiko","Gering","Mittel","Hoch")
A6: 2 | B6: apartments | C6: Kupferdreher Straße | D6: 156 | E6: 150.3 | F6: 0 | G6: 0 | H6: =IF(OR(N(F6)>=0.5,G6>=4),3,IF(OR(N(F6)>=0.3,G6=3),2,IF(OR(N(F6)>=0.1,G6>=1),1,0))) | I6: =CHOOSE(H6+1,"Kein Risiko","Gering","Mittel","Hoch")
A7: 3 | B7: apartments | C7: Bahnstraße | D7: 8 | E7: 120 | F7: 0 | G7: 1 | H7: =IF(OR(N(F7)>=0.5,G7>=4),3,IF(OR(N(F7)>=0.3,G7=3),2,IF(OR(N(F7)>=0.1,G7>=1),1,0))) | I7: =CHOOSE(H7+1,"Kein Risiko","Gering","Mittel","Hoch")
A8: 4 | B8: apartments | C8: Byfanger Straße | D8: 3 | E8: 108.2 | F8: 0 | G8: 0 | H8: =IF(OR(N(F8)>=0.5,G8>=4),3,IF(OR(N(F8)>=0.3,G8=3),2,IF(OR(N(F8)>=0.1,G8>=1),1,0))) | I8: =CHOOSE(H8+1,"Kein Risiko","Gering","Mittel","Hoch")
A9: 5 | B9: apartments | C9: Hofstraße | D9: 6 | E9: 122.7 | F9: 0 | G9: 0 | H9: =IF(OR(N(F9)>=0.5,G9>=4),3,IF(OR(N(F9)>=0.3,G9=3),2,IF(OR(N(F9)>=0.1,G9>=1),1,0))) | I9: =CHOOSE(H9+1,"Kein Risiko","Gering","Mittel","Hoch")
A10: 6 | B10: yes | C10: Colsmanstraße | D10: 7 | E10: 200.9 | F10: 1.0599976 | G10: 0 | H10: =IF(OR(N(F10)>=0.5,G10>=4),3,IF(OR(N(F10)>=0.3,G10=3),2,IF(OR(N(F10)>=0.1,G10>=1),1,0))) | I10: =CHOOSE(H10+1,"Kein Risiko","Gering","Mittel","Hoch")
A11: 7 | B11: apartments | E11: 371.3 | F11: 0.020000458 | G11: 0 | H11: =IF(OR(N(F11)>=0.5,G11>=4),3,IF(OR(N(F11)>=0.3,G11=3),2,IF(OR(N(F11)>=0.1,G11>=1),1,0))) | I11: =CHOOSE(H11+1,"Kein Risiko","Gering","Mittel","Hoch")
A12: 8 | B12: apartments | C12: Kupferdreher Straße | D12: 165 | E12: 192.6 | F12: 0.010002136 | G12: 5 | H12: =IF(OR(N(F12)>=0.5,G12>=4),3,IF(OR(N(F12)>=0.3,G12=3),2,IF(OR(N(F12)>=0.1,G12>=1),1,0))) | I12: =CHOOSE(H12+1,"Kein Risiko","Gering","Mittel","Hoch")
A13: 9 | B13: hospital | C13: Heidbergweg | D13: 22-24 | E13: 2522 | F13: 0.48000336 | G13: 2 | H13: =IF(OR(N(F13)>=0.5,G13>=4),3,IF(OR(N(F13)>=0.3,G13=3),2,IF(OR(N(F13)>=0.1,G13>=1),1,0))) | I13: =CHOOSE(H13+1,"Kein Risiko","Gering","Mittel","Hoch")
A14: 10 | B14: apartments | C14: Narjesstraße | D14: 12 | E14: 244 | F14: 0.030006409 | G14: 0 | H14: =IF(OR(N(F14)>=0.5,G14>=4),3,IF(OR(N(F14)>=0.3,G14=3),2,IF(OR(N(F14)>=0.1,G14>=1),1,0))) | I14: =CHOOSE(H14+1,"Kein Risiko","Gering","Mittel","Hoch")
A15: 11 | B15: public | C15: Benderstraße | D15: 15 | E15: 167.7 | F15: 0 | G15: 1 | H15: =IF(OR(N(F15)>=0.5,G15>=4),3,IF(OR(N(F15)>=0.3,G15=3),2,IF(OR(N(F15)>=0.1,G15>=1),1,0))) | I15: =CHOOSE(H15+1,"Kein Risiko","Gering","Mittel","Hoch")
A16: 12 | B16: kindergarten | C16: Benderstraße | D16: 14 | E16: 490.7 | F16: 0.080001831 | G16: 1 | H16: =IF(OR(N(F16)>=0.5,G16>=4),3,IF(OR(N(F16)>=0.3,G16=3),2,IF(OR(N(F16)>=0.1,G16>=1),1,0))) | I16: =CHOOSE(H16+1,"Kein Risiko","Gering","Mittel","Hoch")
A17: 13 | B17: apartments | C17: Benderstraße | D17: 12 | E17: 168.1 | F17: 0 | G17: 0 | H17: =IF(OR(N(F17)>=0.5,G17>=4),3,IF(OR(N(F17)>=0.3,G17=3),2,IF(OR(N(F17)>=0.1,G17>=1),1,0))) | I17: =CHOOSE(H17+1,"Kein Risiko","Gering","Mittel","Hoch")
A18: 14 | B18: garage | C18: Dixbäume | D18: 78 | E18: 62.6 | F18: 0 | G18: 0 | H18: =IF(OR(N(F18)>=0.5,G18>=4),3,IF(OR(N(F18)>=0.3,G18=3),2,IF(OR(N(F18)>=0.1,G18>=1),1,0))) | I18: =CHOOSE(H18+1,"Kein Risiko","Gering","Mittel","Hoch")
A19: 15 | B19: house | C19: Dixbäume | D19: 75 | E19: 118.2 | F19: 0 | G19: 1 | H19: =IF(OR(N(F19)>=0.5,G19>=4),3,IF(OR(N(F19)>=0.3,G19=3),2,IF(OR(N(F19)>=0.1,G19>=1),1,0))) | I19: =CHOOSE(H19+1,"Kein Risiko","Gering","Mittel","Hoch")
A20: 16 | B20: house | C20: Dixbäume | D20: 81 | E20: 149.5 | F20: 0.010002136 | G20: 0 | H20: =IF(OR(N(F20)>=0.5,G20>=4),3,IF(OR(N(F20)>=0.3,G20=3),2,IF(OR(N(F20)>=0.1,G20>=1),1,0))) | I20: =CHOOSE(H20+1,"Kein Risiko","Gering","Mittel","Hoch")
A21: 17 | B21: kindergarten | C21: Anstockstraße | D21: 11 | E21: 388.7 | F21: 0 | G21: 0 | H21: =IF(OR(N(F21)>=0.5,G21>=4),3,IF(OR(N(F21)>=0.3,G21=3),2,IF(OR(N(F21)>=0.1,G21>=1),1,0))) | I21: =CHOOSE(H21+1,"Kein Risiko","Gering","Mittel","Hoch")
A22: 18 | B22: sports_centre | E22: 457.4 | F22: 0.080001831 | G22: 0 | H22: =IF(OR(N(F22)>=0.5,G22>=4),3,IF(OR(N(F22)>=0.3,G22=3),2,IF(OR(N(F22)>=0.1,G22>=1),1,0))) | I22: =CHOOSE(H22+1,"Kein Risiko","Gering","Mittel","Hoch")
A23: 19 | B23: museum | C23: Kupferdreher Straße | D23: 141-143 | E23: 447.2 | F23: 0.030002594 | G23: 0 | H23: =IF(OR(N(F23)>=0.5,G23>=4),3,IF(OR(N(F23)>=0.3,G23=3),2,IF(OR(N(F23)>=0.1,G23>=1),1,0))) | I23: =CHOOSE(H23+1,"Kein Risiko","Gering","Mittel","Hoch")
A24: 20 | B24: sports_centre | C24: Schwermannstraße | D24: 45 | E24: 1142.7 | F24: 0.049995422 | G24: 0 | H24: =IF(OR(N(F24)>=0.5,G24>=4),3,IF(OR(N(F24)>=0.3,G24=3),2,IF(OR(N(F24)>=0.1,G24>=1),1,0))) | I24: =CHOOSE(H24+1,"Kein Risiko","Gering","Mittel","Hoch")
A25: 21 | B25: apartments | C25: Byfanger Straße | D25: 34 | E25: 177.8 | F25: 0 | G25: 5 | H25: =IF(OR(N(F25)>=0.5,G25>=4),3,IF(OR(N(F25)>=0.3,G25=3),2,IF(OR(N(F25)>=0.1,G25>=1),1,0))) | I25: =CHOOSE(H25+1,"Kein Risiko","Gering","Mittel","Hoch")
A26: 22 | B26: apartments | C26: Dixbäume | D26: 83 | E26: 137.7 | F26: 0 | G26: 2 | H26: =IF(OR(N(F26)>=0.5,G26>=4),3,IF(OR(N(F26)>=0.3,G26=3),2,IF(OR(N(F26)>=0.1,G26>=1),1,0))) | I26: =CHOOSE(H26+1,"Kein Risiko","Gering","Mittel","Hoch")
A27: 23 | B27: church | C27: Dilldorfer Straße | D27: 34 | E27: 837.6 | F27: 0.010002136 | G27: 0 | H27: =IF(OR(N(F27)>=0.5,G27>=4),3,IF(OR(N(F27)>=0.3,G27=3),2,IF(OR(N(F27)>=0.1,G27>=1),1,0))) | I27: =CHOOSE(H27+1,"Kein Risiko","Gering","Mittel","Hoch")
A28: 24 | B28: yes | C28: Eisenhammerweg | D28: 25a | E28: 72.6 | F28: 0 | G28: 1 | H28: =IF(OR(N(F28)>=0.5,G28>=4),3,IF(OR(N(F28)>=0.3,G28=3),2,IF(OR(N(F28)>=0.1,G28>=1),1,0))) | I28: =CHOOSE(H28+1,"Kein Risiko","Gering","Mittel","Hoch")
A29: 25 | B29: office | C29: Deilbachtal | D29: 173 | E29: 2625.9 | G29: 0 | H29: =IF(OR(N(F29)>=0.5,G29>=4),3,IF(OR(N(F29)>=0.3,G29=3),2,IF(OR(N(F29)>=0.1,G29>=1),1,0))) | I29: =CHOOSE(H29+1,"Kein Risiko","Gering","Mittel","Hoch")
A30: 26 | B30: yes | C30: Kampmannbrücke | D30: 37 | E30: 62.8 | F30: 0.20000076 | G30: 0 | H30: =IF(OR(N(F30)>=0.5,G30>=4),3,IF(OR(N(F30)>=0.3,G30=3),2,IF(OR(N(F30)>=0.1,G30>=1),1,0))) | I30: =CHOOSE(H30+1,"Kein Risiko","Gering","Mittel","Hoch")
A31: 27 | B31: parking | E31: 2328.4 | F31: 0.059997559 | G31: 1 | H31: =IF(OR(N(F31)>=0.5,G31>=4),3,IF(OR(N(F31)>=0.3,G31=3),2,IF(OR(N(F31)>=0.1,G31>=1),1,0))) | I31: =CHOOSE(H31+1,"Kein Risiko","Gering","Mittel","Hoch")
A32: 28 | B32: yes | C32: Frauenstein | D32: 121 | E32: 113.8 | F32: 0.020004272 | G32: 0 | H32: =IF(OR(N(F32)>=0.5,G32>=4),3,IF(OR(N(F32)>=0.3,G32=3),2,IF(OR(N(F32)>=0.1,G32>=1),1,0))) | I32: =CHOOSE(H32+1,"Kein Risiko","Gering","Mittel","Hoch")
A33: 29 | B33: commercial | C33: Kupferdreher Straße | D33: 137 | E33: 503.2 | F33: 0.20000076 | G33: 2 | H33: =IF(OR(N(F33)>=0.5,G33>=4),3,IF(OR(N(F33)>=0.3,G33=3),2,IF(OR(N(F33)>=0.1,G33>=1),1,0))) | I33: =CHOOSE(H33+1,"Kein Risiko","Gering","Mittel","Hoch")
A34: 30 | B34: yes | C34: Kupferdreher Straße | D34: 41 | E34: 1294.6 | F34: 0.040000916 | G34: 0 | H34: =IF(OR(N(F34)>=0.5,G34>=4),3,IF(OR(N(F34)>=0.3,G34=3),2,IF(OR(N(F34)>=0.1,G34>=1),1,0))) | I34: =CHOOSE(H34+1,"Kein Risiko","Gering","Mittel","Hoch")
A35: 31 | B35: yes | C35: Kupferdreher Straße | D35: 43 | E35: 1381.6 | F35: 0.23999786 | G35: 2 | H35: =IF(OR(N(F35)>=0.5,G35>=4),3,IF(OR(N(F35)>=0.3,G35=3),2,IF(OR(N(F35)>=0.1,G35>=1),1,0))) | I35: =CHOOSE(H35+1,"Kein Risiko","Gering","Mittel","Hoch")
A36: 32 | B36: yes | E36: 265.8 | F36: 0 | G36: 0 | H36: =IF(OR(N(F36)>=0.5,G36>=4),3,IF(OR(N(F36)>=0.3,G36=3),2,IF(OR(N(F36)>=0.1,G36>=1),1,0))) | I36: =CHOOSE(H36+1,"Kein Risiko","Gering","Mittel","Hoch")
A37: 33 | B37: apartments | C37: Byfanger Straße | D37: 8 | E37: 236.1 | F37: 0 | G37: 0 | H37: =IF(OR(N(F37)>=0.5,G37>=4),3,IF(OR(N(F37)>=0.3,G37=3),2,IF(OR(N(F37)>=0.1,G37>=1),1,0))) | I37: =CHOOSE(H37+1,"Kein Risiko","Gering","Mittel","Hoch")
A38: 34 | B38: yes | C38: Hardenbergufer | E38: 48.2 | F38: 0 | G38: 1 | H38: =IF(OR(N(F38)>=0.5,G38>=4),3,IF(OR(N(F38)>=0.3,G38=3),2,IF(OR(N(F38)>=0.1,G38>=1),1,0))) | I38: =CHOOSE(H38+1,"Kein Risiko","Gering","Mittel","Hoch")
A39: 35 | B39: school | C39: Prinz-Friedrich-Straße | D39: 28a | E39: 1047.2 | F39: 0.010002136 | G39: 0 | H39: =IF(OR(N(F39)>=0.5,G39>=4),3,IF(OR(N(F39)>=0.3,G39=3),2,IF(OR(N(F39)>=0.1,G39>=1),1,0))) | I39: =CHOOSE(H39+1,"Kein Risiko","Gering","Mittel","Hoch")
A40: 36 | B40: yes | C40: Prinz-Friedrich-Straße | D40: 34 | E40: 1332.8 | F40: 0.020000458 | G40: 1 | H40: =IF(OR(N(F40)>=0.5,G40>=4),3,IF(OR(N(F40)>=0.3,G40=3),2,IF(OR(N(F40)>=0.1,G40>=1),1,0))) | I40: =CHOOSE(H40+1,"Kein Risiko","Gering","Mittel","Hoch")
A41: 37 | B41: industrial | C41: Prinz-Friedrich-Straße | D41: 18 | E41: 1085.1 | F41: 0.069999695 | G41: 0 | H41: =IF(OR(N(F41)>=0.5,G41>=4),3,IF(OR(N(F41)>=0.3,G41=3),2,IF(OR(N(F41)>=0.1,G41>=1),1,0))) | I41: =CHOOSE(H41+1,"Kein Risiko","Gering","Mittel","Hoch")
...
